Workbook

Sheet LISTADO
C1: CI COLOMBIAN MINT | K1: Codigo: GMC-FR08
C2: LISTADO DE VERIFICACION | K2: Versión:1
K3: Fecha de aprobación: 01/07/2021
A5: 1. PLANIFICACIÓN DE LA AUDITORIA
A6: FECHA | C6: 2026-07-10 | G6: PROCESO | H6: GEX GESTION EXPORTACIONES
A7: AUDITOR | C7: Erika Mesa / Jimena Zuluaga | G7: AUDITADO | H7: Iván Arias / Dairy Mosquera / Jefferson González
A8: DOCUMENTOS RELACIONADOS | C8: GMC-FR07 Plan Auditorías 2026 · Res. 015/2016 Art. 4º · GMC-FR08 | G8: REQUISITOS | H8: OEA 6.3, OEA 6.7, OEA 6.8, OEA 6.9, OEA 6.10, OEA 6.11
A9: OBJETIVO | C9: Validar el cumplimiento de los requisitos de la resolución 015 de 2016 para el OEA Exportador | G9: ALCANCE | H9: Todos los requisitos OEA de la resolución 015 de 2016 para operador económico autorizado tipo Exportador.
A10: 2. ENTREVISTA
A11: PREGUNTAS | G11: COMENTARIOS | K11: CUMPLE
K12: SI | L12: NO
A13: 1
A14: 2
A15: 3
A16: 4
A17: 5
A18: 6
A19: 7
A20: 8
A21: 9
A22: 10
A24: 3. HALLAZGOS INDIVIDUALES
A28: 4. ASPECTOS POR RESALTAR (AR)
A29: 1
A30: 2
A31: 3
A32: 4
A33: 5
A34: 5. ASPECTOS POR MEJORAR (AM)
A35: 1
A36: 2
A37: 3
A38: 4
A39: 5
A41: REQUISITO | C41: NO CONFORMIDAD (NC) | H41: RIESGO | K41: Nº AC
A42: 1
A43: 2
A44: 3
A45: 4
A46: 5
...

Sheet Banco Preguntas
A1: Requisito | B1: Proceso | C1: Responsable | D1: Descripción del requisito | E1: Preguntas Sugeridas Auditoría Interna
A2: OEA 6.3 | B2: GEX GESTION EXPORTACIONES | C2: =+LISTADO!$H$7 -> Iván Arias / Dairy Mosquera / Jefferson González | D2: Debe tener herramientas que le permitan garantizar la trazabilidad de la carga y del vehículo que la transporta desde el punto de llenado hasta el puerto de embarque al exterior. | E2: ¿Mencione las herramientas que le permiten controlar la trazabilidad de la carga, la ubicación física y la trayectoria de las mercancías a lo largo de la cadena de suministro, desde el punto de llenado hasta el puerto de embarque hacia el exterior; este seguimiento debe realizarse sin considerar los términos Incoterms aplicados en la negociación comercial. Para sustentar, presente evidencia documental vigente de Colombian Mint, tales como: GEX-PR03 (Cadena de Suministro Internacional Exportaciones e Importaciones), GEX-FR01 (Control Trazabilidad de Exportaciones)?
A3: OEA 6.3 | B3: GEX GESTION EXPORTACIONES | C3: =+LISTADO!$H$7 -> Iván Arias / Dairy Mosquera / Jefferson González | D3: Debe tener herramientas que le permitan garantizar la trazabilidad de la carga y del vehículo que la transporta desde el punto de llenado hasta el puerto de embarque al exterior. | E3: ¿Cuáles son los formatos, registros, sistemas informáticos y/o mecanismos implementados, para garantizar la trazabilidad de la carga en tiempo real. ¿Qué registros o documentos (GEX-FR01 (Control Trazabilidad de Exportaciones), GEX-PR01 (Procedimiento Gestión de exportación doré)) demuestran el cumplimiento de lo solicitado?
A4: OEA 6.3 | B4: GEX GESTION EXPORTACIONES | C4: =+LISTADO!$H$7 -> Iván Arias / Dairy Mosquera / Jefferson González | D4: Debe tener herramientas que le permitan garantizar la trazabilidad de la carga y del vehículo que la transporta desde el punto de llenado hasta el puerto de embarque al exterior. | E4: ¿Cuenta con un documento(s), procedimiento(s), instructivo(s), manual(es) con la instrucción para realizar la trazabilidad de la carga, quien, como, cuando y con qué frecuencia se supervisa la operación de comercio exterior? Indique la ubicación en el documento (numeral, ítem, párrafos, página, etc.) Indique versión, fecha e identificación en el SGD. Para sustentar, presente evidencia documental vigente de Colombian Mint, tales como: GEX-PR01 (Procedimiento Gestión de exportación doré), GEX-PR02 (Procedimiento Gestión de exportación concentrados)?
A5: OEA 6.3 | B5: GEX GESTION EXPORTACIONES | C5: =+LISTADO!$H$7 -> Iván Arias / Dairy Mosquera / Jefferson González | D5: Debe tener herramientas que le permitan garantizar la trazabilidad de la carga y del vehículo que la transporta desde el punto de llenado hasta el puerto de embarque al exterior. | E5: ¿Cargue las evidencias de implementación (Ej. Registro fotográfico, listas de chequeo, Reporte de rastreo, correos electrónicos, capturas de pantalla, reporte de escoltas, registro del sistema informático, contrato con la transportadora y/o de sellos satelitales, cláusulas de seguridad, acuerdos, SOP etc.).". ¿Qué registros o documentos (GPC-PR03 (Procedimiento para la Gestión de Servicios con la Transportadora de Va), GEX-PR01 (Procedimiento Gestión de exportación doré)) demuestran el cumplimiento de lo solicitado?
A6: OEA 6.3 | B6: GEX GESTION EXPORTACIONES | C6: =+LISTADO!$H$7 -> Iván Arias / Dairy Mosquera / Jefferson González | D6: Debe tener herramientas que le permitan garantizar la trazabilidad de la carga y del vehículo que la transporta desde el punto de llenado hasta el puerto de embarque al exterior. | E6: ¿según criterios de auditoría OEA (ISO 19011) para el requisito OEA 6.3: Sistema de seguimiento logístico. ¿Qué evidencia objetiva presenta el auditado? Documentos de referencia: GEX-PR01 (Procedimiento Gestión de exportación doré), GEX-PR02 (Procedimiento Gestión de exportación concentrados)?
A7: OEA 6.3 | B7: GEX GESTION EXPORTACIONES | C7: =+LISTADO!$H$7 -> Iván Arias / Dairy Mosquera / Jefferson González | D7: Debe tener herramientas que le permitan garantizar la trazabilidad de la carga y del vehículo que la transporta desde el punto de llenado hasta el puerto de embarque al exterior. | E7: ¿según criterios de auditoría OEA (ISO 19011) para el requisito OEA 6.3: Formatos de trazabilidad (física o digital). ¿Qué evidencia objetiva presenta el auditado? Documentos de referencia: GEX-FR01 (Control Trazabilidad de Exportaciones), GEX-PR01 (Procedimiento Gestión de exportación doré)?
A8: OEA 6.3 | B8: GEX GESTION EXPORTACIONES | C8: =+LISTADO!$H$7 -> Iván Arias / Dairy Mosquera / Jefferson González | D8: Debe tener herramientas que le permitan garantizar la trazabilidad de la carga y del vehículo que la transporta desde el punto de llenado hasta el puerto de embarque al exterior. | E8: ¿Verifique el documento SRF-GU13 (Guía estudio ruta Cartagena). ¿Está vigente, identificado en el SGD, aprobado por la autoridad competente y en aplicación para el requisito OEA 6.3?
A9: OEA 6.3 | B9: GEX GESTION EXPORTACIONES | C9: =+LISTADO!$H$7 -> Iván Arias / Dairy Mosquera / Jefferson González | D9: Debe tener herramientas que le permitan garantizar la trazabilidad de la carga y del vehículo que la transporta desde el punto de llenado hasta el puerto de embarque al exterior. | E9: ¿en la auditoría ARCA (marzo 2025) se registró respecto a OEA 6.3: "En el procedimiento gestión de exportación Doré se establece en la actividad 7 los documento como". ¿Cuál es el estado actual de las acciones correctivas y su verificación efectiva? Evidencia de cierre sugerida: GEX-PR01 (Procedimiento Gestión de exportación doré)?
A10: OEA 6.3 | B10: GEX GESTION EXPORTACIONES | C10: =+LISTADO!$H$7 -> Iván Arias / Dairy Mosquera / Jefferson González | D10: Debe tener herramientas que le permitan garantizar la trazabilidad de la carga y del vehículo que la transporta desde el punto de llenado hasta el puerto de embarque al exterior. | E10: ¿El requisito OEA 6.3 exige: "Debe tener herramientas que le permitan garantizar la trazabilidad de la carga y del vehículo que la transporta desde el punto de llenado hasta el puerto de embarque al exterior." ¿Qué controles operativos y registros demuestran su cumplimiento sostenido en Colombian Mint?
A11: OEA 6.3 | B11: GEX GESTION EXPORTACIONES | C11: =+LISTADO!$H$7 -> Iván Arias / Dairy Mosquera / Jefferson González | D11: Debe tener herramientas que le permitan garantizar la trazabilidad de la carga y del vehículo que la transporta desde el punto de llenado hasta el puerto de embarque al exterior. | E11: ¿El personal entrevistado conoce los requisitos de OEA 6.3 y su responsabilidad en el cumplimiento? Solicite evidencia de socialización, inducción o capacitación?
A12: OEA 6.7 | B12: GEX GESTION EXPORTACIONES | C12: =+LISTADO!$H$7 -> Iván Arias / Dairy Mosquera / Jefferson González | D12: Tener procedimientos documentados para garantizar que la información de despacho o recepción de carga sea veraz, legible y que se cuente con ella antes que se reciba efectivamente la carga. Así mismo que dicha información esté protegida contra cambios, pérdidas o introducción de datos erróneos. | E12: ¿Mencione el documento(s), procedimiento(s), instructivo(s), manual(es) que la documentación y la información cumplen con las condiciones solicitadas en el requisito. Indique la ubicación en el documento (numeral, ítem, párrafos, página, etc.) Indique versión, fecha e identificación en el SGD. Para sustentar, presente evidencia documental vigente de Colombian Mint, tales como: GEX-PR01 (Procedimiento Gestión de exportación doré), GEX-PR02 (Procedimiento Gestión de exportación concentrados)?
A13: OEA 6.7 | B13: GEX GESTION EXPORTACIONES | C13: =+LISTADO!$H$7 -> Iván Arias / Dairy Mosquera / Jefferson González | D13: Tener procedimientos documentados para garantizar que la información de despacho o recepción de carga sea veraz, legible y que se cuente con ella antes que se reciba efectivamente la carga. Así mismo que dicha información esté protegida contra cambios, pérdidas o introducción de datos erróneos. | E13: ¿Cuenta con formato(s) o registro(s) para documentar el cumplimiento de las medidas adoptadas? Indique versión, fecha e identificación en el SGD. Para sustentar, presente evidencia documental vigente de Colombian Mint, tales como: GEX-PR01 (Procedimiento Gestión de exportación doré), GEX-PR02 (Procedimiento Gestión de exportación concentrados)?
... A61: OEA 6.11 | B61: GEX GESTION EXPORTACIONES | C61: =+LISTADO!$H$7 -> Iván Arias / Dairy Mosquera / Jefferson González | D61: Tener procedimientos documentados para el archivo, almacenamiento y protección de la documentación física y electrónica de sus operaciones de su cadena de suministro internacional y su destrucción cuando a ello hubiere lugar. | E61: ¿Existen indicadores o métricas definidos para verificar la eficacia de los controles del requisito OEA 6.11? Presente resultados del último periodo evaluado?
